> “异常”（Exception）这个词表达的是一种“例外”情况，亦即正常情况之外的一种“异常”。

“异常条件”表示在出现什么问题的时候应中止方法或作用域的继续。为了将异常条件与普通问题区分开， 异常条件是非常重要的一个因素。在普通问题的情况下，我们在当前已拥有足够的信息，可在某种程度上解决碰到的问题。而在异常条件的情况下，却无法继续下去，因为当前没有提供解决问题所需的足够多的信 息。此时，我们能做的唯一事情就是跳出当前环境，将那个问题委托给一个更高级的负责人。这便是出现异常时出现的情况。一个简单的例子是“除法”。如可能被零除，就有必要进行检查，确保程序不会冒进，并在那种情况下执行除法。但具体通过什么知道分母是零呢？在那个特定的方法里，在我们试图解决的那个问题的环境中，我们或许知道该如何对待一个零分母。但假如它是一个没有预料到的值，就不能对其进行处理，所以必须产生一个异常，而非不顾一切地继续执行下去。

产生一个异常时，会发生几件事情。

1. 首先，按照与创建Java 对象一样的方法**创建异常对象**：在内存“堆” 里，使用 new 来创建。
2. 随后，停止当前执行路径(记住不可沿这条路径继续下去)，然后从当前的环境中**释放出异常对象的句柄**。
3. 此时，**异常控制机制会接管一切**，并开始查找一个恰当的地方，用于继续程序的执行。这个恰当的地方便是“异常控制器”，它的职责是从问题中恢复，使程序要么尝试另一条执行路径，要么简单地继续。

作为产生异常的一个简单示例，大家可思考一个名为 t 的对象句柄。有些时候，程序可能传递一个尚未初始化的句柄。所以在用那个对象句柄调用一个方法之前，最好进行一番检查。可将与错误有关的信息发送到一个更大的场景中，方法是创建一个特殊的对象，用它代表我们的信息，并将其“掷”(Throw)出我们当前的 场景之外。这就叫作“产生一个异常”或者“掷出一个异常”。下面是它的大概形式

```java
if(t == null) {
  throw new NullPointerException(); 
}
```

这样便“掷”出了一个异常。在当前场景中，它使我们能放弃进一步解决该问题的企图。该问题会被转移到其他更恰当的地方解决。

### 一、异常变量

---

和 Java 的其他任何对象一样，需要用 new 在内存堆里创建异常，并需调用一个构建器。在所有标准异常中，存在着两个构建器：第一个是默认构建器，第二个则需使用一个字串自变量，使我们能在异常里置入相关信息：

```java
if(t == null) {
  throw new NullPointerException("t = null"); 
}
```

稍后，字符串可用各种方法提取出来，就象稍后会展示的那样。

在这儿，关键字 throw 会做出一系列的事情。它首先执行 new 表达式，创建一个不在程序常规执行范围之内的对象。而且理所当然，会为那个对象调用构建器。随后，对象实际会从方法中返回——尽管对象的类型通常并不是方法设计为返回的类型。为深入理解异常控制，可将其想象成另一种返回机制。通过“掷”出一个异常，亦可从原来的作用域中退出。但是会先返回一个值，再退出方法或作用域。 但是，与普通方法返回的相似性到此便全部结束了，因为我们返回的地方与从普通方法调用中返回的地方是迥然有异的（我们结束于一个恰当的异常控制器，它距离异常“掷”出的地方可能相当遥远——在调用堆栈中要低上许多级）。此外，我们可根据需要掷出任何类型的“可掷”对象。典型情况下，我们要为每种不同类型的错误“掷”出一类不同的异常。我们的思路是在异常对象以及挑选的异常对象类型中保存信息，所以在更大场景中的某个人可知道如何对待我们的异常(通常，唯一的信息是异常对象的类型，而异常对象中保存的没什么意义)。



### 二、异常的捕获

---

若某个方法产生一个异常，必须保证该异常能被捕获，并获得正确对待。为理解异常是如何捕获的，首先必须掌握“**警戒区**”的概念。它代表一个特殊的代码区域，有可能产生异常，并在后面跟随用于控制那些异常的代码。

#### 2.1 try 块

若位于一个方法内部，并“掷”出一个异常（或在这个方法内部调用的另一个方法产生了异常），那个方法 就会在异常产生过程中退出。若不想一个 throw 离开方法，可在那个方法内部设置一个特殊的代码块，用它 捕获异常。这就叫作“try 块”，因为要在这个地方“尝试”各种方法调用。try 块属于一种普通的作用域， 用一个try关键字开头：

```java
try {
  // 可能产生异常的代码 
}
```

若用一种不支持异常控制的编程语言全面检查错误，必须用设置和错误检测代码将每个方法都包围起来—— 即便多次调用相同的方法。而在使用了异常控制技术后，可将所有东西都置入一个 try 块内，在同一地点捕获所有异常。这样便可极大简化我们的代码，并使其更易辨读，因为代码本身要达到的目标再也不会与繁复的错误检查混淆。

#### 2.2 异常控制器

生成的异常必须在某个地方中止。这个“地方”便是异常控制器或者异常控制模块。而且针对想捕获的每种异常类型，都必须有一个相应的异常控制器。异常控制器紧接在 try 块后面，且用 catch(捕获)关键字标记。如下所示：

```java
try {
  // Code that might generate exceptions
} catch(Type1 id1) {
  // Handle exceptions of Type1
} catch(Type2 id2) {
  // Handle exceptions of Type2
} catch(Type3 id3) {
  // Handle exceptions of Type3
}
// etc...
```

每个 catch 从句——即异常控制器——都类似一个小型方法，它需要采用一个特定类型的自变量。可在控制器内部使用标识符(id1，id2 等等)，就象一个普通的方法自变量那样。我们有时也根本不使用标识符，因为异常类型已提供了足够的信息，可有效处理异常。但即使不用，标识符也必须就位。 控制器必须“紧接”在 try 块后面。若“掷”出一个异常，异常控制机制就会搜寻自变量与异常类型相符的第一个控制器。随后，它会进入那个 catch 从句，并认为异常已得到控制(一旦 catch 从句结束，对控制器的搜索也会停止)。只有相符的 catch 从句才会得到执行。

**在try 块内部，请注意大量不同的方法调用可能生成相同的异常，但只需要一个控制器。**

>**中断与恢复**
>
>在异常控制理论中，共存在两种基本方法。在“**中断**”方法中(Java 和 C++提供了对这种方法的支持)，我们假定错误非常关键，没有办法返回异常发生的地方。无论谁只要“掷”出一个异常，就表明没有办法补救错误，而且也不希望再回来。另一种方法叫作“**恢复**”。它意味着异常控制器有责任来纠正当前的状况，然后取得出错的方法，假定下一次会成功执行。若使用恢复，意味着在异常得到控制以后仍然想继续执行。在这种情况下，我们的异常更象 一个方法调用——我们用它在 Java 中设置各种各样特殊的环境，产生类似于“恢复”的行为(换言之，此时 不是“掷”出一个异常，而是调用一个用于解决问题的方法)。另外，也可以将自己的 try 块置入一个 while循环里，用它不断进入try块，直到结果满意时为止。 从历史的角度看，若程序员使用的操作系统支持可恢复的异常控制，最终都会用到类似于中断的代码，并跳过恢复进程。所以尽管“恢复”表面上十分不错，但在实际应用中却显得困难重重。其中决定性的原因可能是：我们的控制模块必须随时留意是否产生了异常，以及是否包含了由产生位置专用的代码。这便使代码很难编写和维护——大型系统尤其如此，因为异常可能在多个位置产生。

#### 2.3 异常规范

对那些要调用方法的客户程序员，我们要通知他们可能从自己的方法里“掷”出异常。这是一种有礼貌的做法，只有它才能使客户程序员准确地知道要编写什么代码来捕获所有潜在的异常。为解决这个问题，Java 提供了一种特殊的语法格式(并强迫我们采用)，以便礼貌地告诉客户程序员该方法会“掷”出什么异常，令对方方便地加以控制。这便是这里要讲述的“异常规范”，**它属于方法声明的一部分，位于自变量(参数)列表的后面**。 异常规范采用了一个额外的关键字：`throws`；后面跟随全部潜在的异常类型。因此，方法定义看起来应像下面这个样子：

```java
void f() throws tooBig, tooSmall, divZero {
  //...
}
```

它意味着不会从方法里“掷”出异常(除类型为RuntimeException 的异常以外，它可能从任何地方掷出)。 但不能完全依赖异常规范——假若方法造成了一个异常，但没有对其进行控制，编译器会侦测到这个情况， 并告诉我们必须控制异常，或者指出应该从方法里“掷”出一个异常规范。通过坚持从顶部到底部排列异常规范，Java 可在编译期保证异常的正确性。

我们在这个地方可采取欺骗手段:要求“掷”出一个并没有发生的异常。**编译器能理解我们的要求，并强迫使用这个方法的用户当作真的产生了那个异常处理**。在实际应用中，可将其作为那个异常的一个“占位符”使用。这样一来，以后可以方便地产生实际的异常，毋需修改现有的代码。

#### 2.4 捕获所有异常

我们可创建一个控制器，令其捕获所有类型的异常。具体的做法是捕获基础类异常类型 Exception(也存在其他类型的基础异常，但Exception 是适用于几乎所有编程活动的基础)。如下所示：

```java
catch(Exception e) {
  System.out.println("caught an exception");
}
```

这段代码能捕获任何异常，所以**在实际使用时最好将其置于控制器列表的末尾**，防止跟随在后面的任何特殊异常控制器失效。

对于程序员常用的所有异常类来说，由于 Exception 类是它们的基础，所以我们不会获得关于异常太多的信息，但可调用来自它的基础类Throwable 的方法：String getMessage() 获得详细的消息。返回对 Throwable 的一段简要说明，其中包括详细的消息(如果有的话)。

```java
void printStackTrace()
void printStackTrace(PrintStream)
```

打印出 Throwable 和 Throwable 的调用堆栈路径。调用堆栈显示出将我们带到异常发生地点的方法调用的顺序。第一个版本会打印出标准错误，第二个则打印出我们的选择流程。若在 Windows 下工作，就不能重定向标准错误。因此，我们一般愿意使用第二个版本，并将结果送给 System.out;这样一来，输出就可重定向到我们希望的任何路径。

除此以外，我们还可从 Throwable 的基础类Object(所有对象的基础类型)获得另外一些方法。对于异常控制来说，其中一个可能有用的是 getClass()，它的作用是返回一个对象，用它代表这个对象的类。我们可依次用getName()或toString()查询这个Class类的名字。亦可对Class对象进行一些复杂的操作，尽管那些操作在异常控制中是不必要的。下面是一个特殊的例子，它展示了Exception方法的使用：

```java
public class ExceptionMethods {
  public static void main(String[] args) {

    try {
      throw new Exception("Here's my Exception"); 
    } catch(Exception e) {
      System.out.println("Caught Exception");
      System.out.println("e.getMessage(): " + e.getMessage());
      System.out.println("e.toString(): " + e.toString());
      System.out.println("e.printStackTrace():");
      e.printStackTrace();
    } }

}
```

该程序输出如下：

```
Caught Exception
e.getMessage(): Here's my Exception
e.toString(): java.lang.Exception: Here's my Exception e.printStackTrace():
java.lang.Exception: Here's my Exception
at ExceptionMethods.main
```

可以看到，该方法连续提供了大量信息——每类信息都是前一类信息的一个子集。

#### 2.5 重新掷出异常

在某些情况下，我们想重新掷出刚才产生过的异常，特别是在用Exception 捕获所有可能的异常时。由于我们已拥有当前异常的句柄，所以只需简单地重新掷出那个句柄即可。

```java
catch(Exception e) {
  System.out.println("一个异常已经产生");
  throw e;
}
```

重新“掷”出一个异常导致异常进入更高一级环境的异常控制器中。用于同一个 try 块的任何更进一步的 catch 从句仍然会被忽略。此外，与异常对象有关的所有东西都会得到保留，所以用于捕获特定异常类型的更高一级的控制器可以从那个对象里提取出所有信息。若只是简单地重新掷出当前异常，我们打印出来的、与 printStackTrace()内的那个异常有关的信息会与异常的起源地对应，而不是与重新掷出它的地点对应。**若想安装新的堆栈跟踪信息，可调用 fillInStackTrace()，它会返回一个特殊的异常对象**。这个异常的创建过程如下：将当前堆栈的信息填充到原来的异常对象里。

```java
public class Rethrowing {
  public static void f() throws Exception {
    System.out.println("originating the exception in f()");
    throw new Exception("thrown from f()");
  }

  public static void g() throws Throwable { 
    try {
      f();
    } catch(Exception e) {
      System.out.println("Inside g(), e.printStackTrace()");
      e.printStackTrace();
      throw e; // 17
      // throw e.fillInStackTrace(); // 18
    } }

  public static void
    main(String[] args) throws Throwable {
    try { 
      g();
    } catch(Exception e) { 
      System.out.println("Caught in main, e.printStackTrace()"); 
      e.printStackTrace();
    } 
  }
}
```

注意第 17 行没有设为注释行。它的输出结果如下：

```
originating the exception in f() Inside g(), e.printStackTrace() java.lang.Exception: thrown from f()
    at Rethrowing.f(Rethrowing.java:8)
    at Rethrowing.g(Rethrowing.java:12) at Rethrowing.main(Rethrowing.java:24)
Caught in main, e.printStackTrace() java.lang.Exception: thrown from f()
    at Rethrowing.f(Rethrowing.java:8)
    at Rethrowing.g(Rethrowing.java:12) at Rethrowing.main(Rethrowing.java:24)
```

由于使用的是fillInStackTrace()，第18行成为异常的新起点。针对g()和main()，Throwable类必须在异常规格中出现，因为fillInStackTrace()会生成一个Throwable 对象的句柄。由于 Throwable 是 Exception 的一个基础类，所以有可能获得一个能够“掷”出的对象(具有 Throwable属性)，但却并非一个Exception(异常)。因此，在main()中用于Exception的句柄可能丢失自己的目标。为保证所有东西均井然有序，编译器强制Throwable 使用一个异常规范。举个例子来说，下述程序的异常便不会在 main()中被捕获到：

```java
public class ThrowOut {
  public static void main(String[] args) throws Throwable {
    try {
      throw new Throwable();
    } catch(Exception e) { 
      System.out.println("Caught in main()");
    } 
  }
}
```

也有可能从一个已经捕获的异常重新“掷”出一个不同的异常。但假如这样做，会得到与使用 fillInStackTrace()类似的效果：与异常起源地有关的信息会全部丢失，我们留下的是与新的 throw 有关的信息。如下所示：

```java
public class RethrowNew {
  public static void f() throws Exception {
    System.out.println("originating the exception in f()");
    throw new Exception("thrown from f()");
  }

  public static void main(String[] args) { 
    try {
      f();
    } catch(Exception e) {
      System.out.println("Caught in main, e.printStackTrace()");
      e.printStackTrace();
      throw new NullPointerException("from main"); 
    }
  }
}
```

输出如下：

```
originating the exception in f() Caught in main, e.printStackTrace() java.lang.Exception: thrown from f()
  at RethrowNew.f(RethrowNew.java:8)
  at RethrowNew.main(RethrowNew.java:13) java.lang.NullPointerException: from main
  at RethrowNew.main(RethrowNew.java:18)
```

最后一个异常只知道自己来自 main()，而非来自 f()。注意 Throwable 在任何异常规范中都不是必需的。

永远不必关心如何清除前一个异常，或者与之有关的其他任何异常。它们都属于用 new 创建的、以内存堆为基础的对象，所以垃圾收集器会自动将其清除。



### 三、标准Java异常

`Throwable`类**对可以作为异常“掷”出的所有东西进行了描述**。Throwable对象有两种常规类型(亦即“从Throwable 继承”)。

1. Error 代表编译期和系统错误，一般不必特意捕获它们(除在特殊情况以外)。
2. Exception 是可以从任何标准 Java 库的类方法中“掷”出的基本类型。此外，它们亦可从我们自己的方法以及运行期偶发事件中“掷”出。

**java.lang.Exception 这是程序能捕获的基本异常**。其他异常都是从它衍生出去的。这里要注意的是异常的名字代表发生的问题，而且异常名通常都是精心挑选的，可以很清楚地说明到底发生了什么事情。

#### 3.1 RuntimeException 的特殊情况

```java
if(t == null)
  throw new NullPointerException();
```

看起来似乎在传递进入一个方法的每个句柄中都必须检查 null(因为不知道调用者是否已传递了一个有效的句柄)，这无疑是相当可怕的。它属于 Java 进行的标准运行期检查的一部分。**若对一个空句柄发出了调用，Java会自动产生一个NullPointerException异常**。所以上述代码在任何情况下都是多余的。

这个类别里含有一系列异常类型。它们全部由 Java 自动生成，无需我们亲自动手把它们包含到自己的异常规范里。最方便的是，通过将它们置入单独一个名为 `RuntimeException` 的基础类下面，它们全部组合到一起。 这是一个很好的继承例子：**它建立了一系列具有某种共通性的类型，都具有某些共通的特征与行为**。此外，没必要专门写一个异常规范，指出一个方法可能会“掷”出一个 RuntimeException，因为已经假定可能出现那种情况。由于它们用于指出编程中的错误，所以几乎永远不必专门捕获一个“运行期异常”—— RuntimeException——它在默认情况下会自动得到处理。若必须检查 RuntimeException，代码就会变得相当繁复。**在我们自己的包里，可选择“掷”出一部分 RuntimeException。如果不捕获这些异常，又会出现什么情况呢？由于编译器并不强制异常规范捕获它们，所以假如不捕获的话，一个 RuntimeException 可能过滤掉我们到达 main()方法的所有途径**。为体会此时发生的事情，请试试下面这个例子：

```java
public class NeverCaught { 
  static void f() {
    throw new RuntimeException("From f()"); 
  }
  static void g() { 
    f();
  }
  public static void main(String[] args) {
    g(); 
  }
}
```

一个 RuntimeException(或者从它继承的任何东西)属于一种特殊情况，因为编译器不要求为这些类型指定异常规范。
输出如下：

```
Exception in thread "main" java.lang.RuntimeException: From f()
  at com.chance.util.Test.f(Test.java:12)
  at com.chance.util.Test.g(Test.java:16)
  at com.chance.util.Test.main(Test.java:20)
```

所以答案就是：假若一个RuntimeException获得到达main()的所有途径，同时不被捕获，那么当程序退出时，会为那个异常调用 printStackTrace()。注意也许能在自己的代码中仅忽略 RuntimeException，因为编译器已正确实行了其他所有控制。因为 RuntimeException 在此时代表一个编程错误：

1. 一个我们不能捕获的错误(例如，由客户程序员接收传递给自己方法的一个空句柄)。
2. 作为一名程序员，一个应在自己的代码中检查的错误(如 ArrayIndexOutOfBoundException，此时应注意数组的大小)。



### 四、创建自己的异常

---

并不一定非要使用 Java 异常。经常都需要创建自己的异常，以便指出自己的库可能生成的一个特殊错误——但创建 Java 分级结构的时候，这个错误是无法预知的。为创建自己的异常类，必须从一个现有的异常类型继承——最好在含义上与新异常近似。继承一个异常：

```java
class MyException extends Exception {
  public MyException() {

  }
  public MyException(String msg) {
    super(msg);
  }
}

public class Inheriting {
  
  public static void f() throws MyException {
    System.out.println("Throwing MyException from f()");
    throw new MyException();
  }
  
  public static void g() throws MyException {
    System.out.println("Throwing MyException from g()");
    throw new MyException("Originated in g()");
  }
  
  public static void main(String[] args) {
    try {
      f();
    } catch(MyException e) {
      e.printStackTrace(); 
    }
    try {
      g();
    } catch(MyException e) {
      e.printStackTrace();
    }
  }
}
```

继承在创建新类时发生：

```java
class MyException extends Exception {
  public MyException() {}

  public MyException(String msg) {
    super(msg);
  }
}
```

这里的关键是“extends Exception”，它的意思是：除包括一个 Exception 的全部含义以外，还有更多的含义。增加的代码数量非常少——实际只添加了两个构建器，对 MyException 的创建方式进行了定义。请记住，假如我们不明确调用一个基础类构建器，编译器会自动调用基础类默认构建器。在第二个构建器中，通过使用 super 关键字，明确调用了带有一个 String 参数的基础类构建器。

由于异常不过是另一种形式的对象，所以可以继续这个进程，进一步增强异常类的能力。但要注意，对使用自己这个包的客户程序员来说，他们可能错过所有这些增强。因为他们可能只是简单地寻找准备生成的异常，除此以外不做任何事情——这是大多数 Java 库异常的标准用法。若出现这种情况，有可能创建一个新异常类型，其中几乎不包含任何代码：

```java
class SimpleException extends Exception {
}
```

它要依赖编译器来创建默认构建器(会自动调用基础类的默认构建器)。当然，在这种情况下，我们不会得到一个 SimpleException(String)构建器，但它实际上也不会经常用到。



### 五、异常的限制

---

方法覆盖中的异常限制：

当一个子类覆盖父类的方法时，子类方法抛出的受检异常不能比父类方法抛出的异常更广泛。这意味着子类方法可以抛出比父类方法更少或相同的异常，但不能抛出更多或更广泛的异常。

```java
class Parent {
  public void doSomething() throws IOException {
    // 父类方法实现
  }
}

class Child extends Parent {
  @Override
  public void doSomething() throws FileNotFoundException { 
    // FileNotFoundException 是 IOException 的子类
    // 子类方法实现
  }
}
```

在上面的例子中，`Child` 类的方法可以抛出 `FileNotFoundException`，因为它是 `IOException` 的子类。但是，不能声明抛出 `Exception`，因为 `Exception` 是 `IOException` 的父类，会扩大异常的范围。



### 六、用finally清除

---

- 定义：finally 块是一个可选的语句块，可以与 try 和 catch 块一起使用。它包含了保证无论是否发生异常都必须执行的代码。
- 用法：finally 块紧跟在 try-catch 块之后，可以存在没有 catch 块的 try-finally 组合。

在编程中，资源管理是一项重要的任务。资源包括**文件**、**数据库连接**、**网络套接字**等。在不再需要这些资源时，应该及时释放它们，以避免资源泄漏。finally 块确保了清理代码总是执行，即使在遇到异常的情况下也是如此。

#### 6.1 特殊情况

- 系统退出：如果在 try 或 catch 块中调用了 `System.exit()` 方法，finally 块将不会执行，因为 JVM 进程会立即终止。
- 线程中断：如果线程在执行 try 或 catch 块时被中断，finally 块仍然会执行。

#### 6.2 结合自动资源管理（ARM）

automatic resource management

在Java 7引入的try-with-resources语句极大简化了资源管理，减少了使用finally块的需要。try-with-resources自动处理资源的关闭：

```java
public class FileOperations {
  public static void main(String[] args) {
    try (FileInputStream fis = new FileInputStream("file.txt")) {
      // 进行文件操作
    } catch (IOException e) {
      e.printStackTrace();
    }
  }
}
```

在这个例子中，FileInputStream 会自动在 try 块结束时关闭。

#### 6.3 丢失的异常

在程序执行过程中抛出了一个异常，但由于某种原因，这个异常没有被适当地捕获和处理，甚至被覆盖或忽略，导致程序无法正确地反映出错误情况。特别是在使用 finally 块时，**如果在 finally 块中抛出了另一个异常，这个新的异常会覆盖掉之前抛出的异常，导致原始异常丢失**。



### 七、关闭资源的异常处理

---

#### 7.1 使用 finally 块关闭资源

资源如文件、数据库连接等需要在使用完毕后及时关闭。传统上，这种资源管理通常在 finally 块中进行。示例：

```java
public class FileOperations {
  public static void main(String[] args) {
    FileInputStream fis = null;
    try {
      fis = new FileInputStream("file.txt");
      // 进行文件操作
    } catch (IOException e) {
      e.printStackTrace();
    } finally {
      if (fis != null) {
        try {
          fis.close();
        } catch (IOException e) {
          e.printStackTrace();
        }
      }
    }
  }
}
```

在这个例子中，无论是否发生异常，finally 块中的代码都会执行，确保 FileInputStream 被关闭。

#### 7.2 构建器模式中的异常处理

当构建器模式涉及资源管理时，特别是在构建复杂对象时，需要考虑如何确保资源的正确关闭。下面是一个将构建器模式与资源管理结合的示例：

```java
import java.io.*;

public class ResourceManagingObject {
  private final FileInputStream fis;

  public static class Builder {
    private String fileName;

    public Builder fileName(String fileName) {
      this.fileName = fileName;
      return this;
    }

    public ResourceManagingObject build() throws IOException {
      return new ResourceManagingObject(this);
    }
  }

  private ResourceManagingObject(Builder builder) throws IOException {
    this.fis = new FileInputStream(builder.fileName);
  }

  public void process() throws IOException {
    // 进行文件处理操作
    int data = fis.read();
    // 其他处理逻辑
  }

  public void close() throws IOException {
    if (fis != null) {
      fis.close();
    }
  }

  public static void main(String[] args) {
    ResourceManagingObject obj = null;
    try {
      obj = new ResourceManagingObject.Builder()
        .fileName("file.txt")
        .build();
      obj.process();
    } catch (IOException e) {
      e.printStackTrace();
    } finally {
      if (obj != null) {
        try {
          obj.close();
        } catch (IOException e) {
          e.printStackTrace();
        }
      }
    }
  }
}
```

#### 7.3 使用 try-with-resources 进行资源管理

自Java 7引入try-with-resources语句以来，资源管理变得更加简洁和安全。try-with-resources语句确保了资源会在语句结束时自动关闭，无需显式地在 finally 块中关闭资源。

```java
import java.io.*;

public class ResourceManagingObject implements Closeable {
  private final FileInputStream fis;

  public static class Builder {
    private String fileName;

    public Builder fileName(String fileName) {
      this.fileName = fileName;
      return this;
    }

    public ResourceManagingObject build() throws IOException {
      return new ResourceManagingObject(this);
    }
  }

  private ResourceManagingObject(Builder builder) throws IOException {
    this.fis = new FileInputStream(builder.fileName);
  }

  public void process() throws IOException {
    // 进行文件处理操作
    int data = fis.read();
    // 其他处理逻辑
  }

  @Override
  public void close() throws IOException {
    if (fis != null) {
      fis.close();
    }
  }

  public static void main(String[] args) {
    try (ResourceManagingObject obj = new ResourceManagingObject.Builder()
         .fileName("file.txt")
         .build()) {
      obj.process();
    } catch (IOException e) {
      e.printStackTrace();
    }
  }
}
```

在这个改进的示例中，ResourceManagingObject 实现了 `Closeable` 接口，并在 try-with-resources 块中使用它。这样，资源会在 try 块结束时自动关闭，即使发生异常也能确保资源正确释放。



### 八、异常匹配

---

1. 按照声明顺序匹配： 异常处理程序**按照 catch 块的声明顺序进行匹配**。当一个异常被抛出时，程序会依次检查每个 catch 块，直到找到与抛出异常类型匹配的 catch 块为止。如果找到了匹配的 catch 块，执行其中的处理代码，然后退出整个 try-catch 结构。如果没有找到匹配的 catch 块，则异常会被传播到调用者。
2. 精确匹配和多态性： 异常匹配机制遵循面向对象的多态性原则，这意味着子类异常会优先于父类异常进行匹配。如果一个 catch 块声明了一个异常类型，该类型与抛出的异常类型相同或是其超类，则认为匹配成功。

```java
class BaseException extends Exception {}
class DerivedException extends BaseException {}

public class ExceptionMatching {
  public static void main(String[] args) {
    try {
      throw new DerivedException();
    } catch (DerivedException e) {
      System.out.println("Caught DerivedException");
    } catch (BaseException e) {
      System.out.println("Caught BaseException");
    } catch (Exception e) {
      System.out.println("Caught Exception");
    }
  }
}
```

在这个例子中，DerivedException 是 BaseException 的子类。抛出 DerivedException 后，程序会按照 catch 块的顺序进行匹配：

1. 首先检查第一个 catch 块，类型是 DerivedException，匹配成功。
2. 执行第一个 catch 块中的代码，打印 "Caught DerivedException"。
3. 跳过后续的 catch 块，因为异常已经被处理。

在编写 catch 块时，应从最具体的异常类型到最一般的异常类型进行排序。具体异常（子类异常）应该在前，一般异常（父类异常）应该在后。否则，会出现编译错误，因为编译器检测到先前的 catch 块已经捕获了所有可能的子类异常，后续的 catch 块将永远无法到达。

```java
public class ExceptionMatching {
  public static void main(String[] args) {
    try {
      throw new DerivedException();
    } catch (BaseException e) {
      System.out.println("Caught BaseException");
    } catch (DerivedException e) { // This block is unreachable
      System.out.println("Caught DerivedException");
    } catch (Exception e) {
      System.out.println("Caught Exception");
    }
  }
}
```

编译器会报错，因为 DerivedException 永远不会被捕获。



### 九、异常准则

---

#### 9.1 不要忽略异常

每当捕获异常时，务必处理它或明确地将其重新抛出。不应仅仅因为不想处理而忽略异常。

```java
try {
  // Some code that may throw an exception
} catch (Exception e) {
  // Empty catch block (bad practice)
}
```

#### 9.2 捕获特定的异常

尽量捕获特定的异常类型，而不是使用一个通用的 Exception 类来捕获所有异常。这可以帮助更好地理解和处理不同的异常情况。

```java
try {
  // Some code that may throw an IOException
} catch (IOException e) {
  // Handle IOException
}
```